Workbook

Sheet Dashboard
B1: Repair | H1: Trane Building Advantage | N1: Trane Rental | T1: Maintenance-TraneSELECT | Z1: Startup | AF1: Parts-OTC | AL1: TOTAL | AT1: Repair | AZ1: Trane Building Advantage | BF1: Trane Rental | BL1: Maintenance-TraneSELECT | BR1: Startup | BX1: Parts-OTC | CD1: TOTAL | CL1: Repair | CO1: TBA | CR1: Trane Rental | CU1: Maintenance-TS | CX1: Startup | DA1: Parts-OTC | DD1: TOTAL | DI1: Repair | DL1: TBA | DO1: Trane Rental | DR1: Maintenance-TS | DU1: Startup | DX1: Parts-OTC | EA1: TOTAL | EF1: % EOD | EG1: < 6 mth old | EH1: Repair | EK1: TBA | EN1: Trane Rental | EQ1: Maintenance-TS | ET1: Startup | EX1: % EOD | EY1: < 3 mth old | EZ1: Parts-OTC | FD1: TOTAL
B2: Backlog Total | E2: Orders YTD | H2: Backlog Total | K2: Orders YTD | N2: Backlog Total | Q2: Orders YTD | T2: Backlog Total | W2: Orders YTD | Z2: Backlog Total | AC2: Orders YTD | AF2: Backlog Total | AI2: Orders YTD | AL2: Backlog Total | AO2: Orders YTD | AT2: Backlog Month | AW2: Burn Rate | AZ2: Backlog Month | BC2: Burn Rate | BF2: Backlog Month | BI2: Burn Rate | BL2: Backlog Month | BO2: Burn Rate | BR2: Backlog Month | BU2: Burn Rate | BX2: Backlog Month | CA2: Burn Rate | CD2: Backlog Month | CG2: Burn Rate | CL2: Backlog Month+1 | CO2: Backlog Month+1 | CR2: Backlog Month+1 | CU2: Backlog Month+1 | CX2: Backlog Month+1 | DA2: Backlog Month+1 | DD2: Backlog Month+1 | DI2: Backlog Month+2 | DL2: Backlog Month+2 | DO2: Backlog Month+2 | DR2: Backlog Month+2 | DU2: Backlog Month+2 | DX2: Backlog Month+2 | EA2: Backlog Month+2 | EH2: QP | EK2: QP | EN2: QP | EQ2: QP | ET2: QP | EZ2: QP | FD2: QP
B3: 2026 | C3: 2025 | D3: VPY | E3: 2026 | F3: 2025 | G3: VPY | H3: 2026 | I3: 2025 | J3: VPY | K3: 2026 | L3: 2025 | M3: VPY | N3: 2026 | O3: 2025 | P3: VPY | Q3: 2026 | R3: 2025 | S3: VPY | T3: 2026 | U3: 2025 | V3: VPY | W3: 2026 | X3: 2025 | Y3: VPY | Z3: 2026 | AA3: 2025 | AB3: VPY | AC3: 2026 | AD3: 2025 | AE3: VPY | AF3: 2026 | AG3: 2025 | AH3: VPY | AI3: 2026 | AJ3: 2025 | AK3: VPY | AL3: 2026 | AM3: 2025 | AN3: VPY | AO3: 2026 | AP3: 2025 | AQ3: VPY | AT3: 2026 | AU3: 2025 | AV3: VPY | AW3: 2026 | AX3: 2025 | AY3: VPY | AZ3: 2026 | BA3: 2025 | BB3: VPY | BC3: 2026 | BD3: 2025 | BE3: VPY | BF3: 2026 | BG3: 2025 | BH3: VPY | BI3: 2026 | BJ3: 2025 | BK3: VPY | BL3: 2026 | BM3: 2025 | BN3: VPY | BO3: 2026 | BP3: 2025 | BQ3: VPY | BR3: 2026 | BS3: 2025 | BT3: VPY | BU3: 2026 | BV3: 2025 | BW3: VPY | BX3: 2026 | BY3: 2025 | BZ3: VPY | CA3: 2026 | CB3: 2025 | CC3: VPY | CD3: 2026 | CE3: 2025 | CF3: VPY | CG3: 2026 | CH3: 2025 | CI3: VPY | CL3: 2026 | CM3: 2025 | CN3: VPY | CO3: 2026 | CP3: 2025 | CQ3: VPY | CR3: 2026 | CS3: 2025 | CT3: VPY | CU3: 2026 | CV3: 2025 | CW3: VPY | CX3: 2026 | CY3: 2025 | CZ3: VPY | DA3: 2026 | DB3: 2025 | DC3: VPY | DD3: 2026 | DE3: 2025 | DF3: VPY | DI3: 2026 | DJ3: 2025 | DK3: VPY | DL3: 2026 | DM3: 2025 | DN3: VPY | DO3: 2026 | DP3: 2025 | DQ3: VPY | DR3: 2026 | DS3: 2025 | DT3: VPY | DU3: 2026 | DV3: 2025 | DW3: VPY | DX3: 2026 | DY3: 2025 | DZ3: VPY | EA3: 2026 | EB3: 2025 | EC3: VPY | EH3: 2026 | EI3: 2025 | EJ3: VPY | EK3: 2026 | EL3: 2025 | EM3: 2026 | EN3: 2026 | EO3: 2025 | EP3: VPY | EQ3: 2026 | ER3: 2025 | ES3: VPY | ET3: 2026 | EU3: 2025 | EV3: VPY | EZ3: 2026 | FA3: 2025 | FB3: VPY | FD3: 2026 | FE3: 2025 | FF3: VPY
A4: IDA | B4: =Serviceorderfile_Current!$W522 -> 73 | C4: =Serviceorderfile_PREVIOUS!$W522 -> 149 | D4: =IF(C4>0,B4/C4-1,1) -> -0.51006711 | E4: ='YOY Orders'!$J17 -> 57 | F4: ='YOY Orders'!$B17 -> 161 | G4: =IF(F4>0,E4/F4-1,1) -> -0.64596273 | H4: =Serviceorderfile_Current!$W524 -> 0 | I4: =Serviceorderfile_PREVIOUS!$W524 -> 0 | J4: =IF(I4>0,H4/I4-1,1) -> 1 | K4: ='YOY Orders'!$K17 -> 0 | L4: ='YOY Orders'!$C17 -> 10 | M4: =IF(L4>0,K4/L4-1,1) -> -1 | N4: =Serviceorderfile_Current!$W523 -> 0 | O4: =Serviceorderfile_PREVIOUS!$W523 -> 0 | P4: =IF(O4>0,N4/O4-1,1) -> 1 | Q4: ='YOY Orders'!$O17 -> 0 | R4: ='YOY Orders'!$G17 -> 0 | S4: =IF(R4>0,Q4/R4-1,1) -> 1 | T4: =Serviceorderfile_Current!$W525 -> 141 | U4: =Serviceorderfile_PREVIOUS!$W525 -> 135 | V4: =IF(U4>0,T4/U4-1,1) -> 0.044444444 | W4: ='YOY Orders'!$L17 -> 126 | X4: ='YOY Orders'!$D17 -> 181 | Y4: =IF(X4>0,W4/X4-1,1) -> -0.3038674 | Z4: =Serviceorderfile_Current!$W526 -> 4 | AA4: =Serviceorderfile_PREVIOUS!$W526 -> 9 | AB4: =IF(AA4>0,Z4/AA4-1,1) -> -0.55555556 | AC4: ='YOY Orders'!$N17 -> 13 | AD4: ='YOY Orders'!$F17 -> 83 | AE4: =IF(AD4>0,AC4/AD4-1,1) -> -0.84337349 | AF4: =Serviceorderfile_Current!$W520 -> 293 | AG4: =Serviceorderfile_PREVIOUS!$W520 -> 262 | AH4: =IF(AG4>0,AF4/AG4-1,1) -> 0.11832061 | AI4: ='YOY Orders'!$M17 -> 768 | AJ4: ='YOY Orders'!$E17 -> 1214 | AK4: =IF(AJ4>0,AI4/AJ4-1,1) -> -0.36738056 | AL4: =B4+T4+Z4+AF4+N4+H4 -> 511 | AM4: =C4+U4+AA4+AG4+O4+I4 -> 555 | AN4: =IF(AM4>0,AL4/AM4-1,1) -> -0.079279279 | AO4: =E4+W4+AC4+AI4+Q4+K4 -> 964 | AP4: =F4+X4+AD4+AJ4+R4+L4 -> 1649 | AQ4: =IF(AP4>0,AO4/AP4-1,1) -> -0.41540327 | AS4: IDA | AT4: =Serviceorderfile_Current!$I522*Serviceorderfile_Current!$U522 -> 18 | AU4: =Serviceorderfile_PREVIOUS!$I522*Serviceorderfile_PREVIOUS!$U522 -> 37 | AV4: =IF(AU4>0,AT4/AU4-1,1) -> -0.51351351 | AW4: =AT4/B4 -> 0.24657534 | AX4: =AU4/C4 -> 0.24832215 | AY4: =(AW4-AX4)*100 -> -0.17468052 | AZ4: =Serviceorderfile_Current!$I524*Serviceorderfile_Current!$U524 -> 0 | BA4: =Serviceorderfile_PREVIOUS!$I524*Serviceorderfile_PREVIOUS!$U524 -> 0 | BB4: =IF(BA4>0,AZ4/BA4-1,1) -> 1 | BC4: =AZ4/H4 -> #DIV/0! | BD4: =BA4/I4 -> #DIV/0! | BE4: =(BC4-BD4)*100 -> #DIV/0! | BF4: =Serviceorderfile_Current!$I523*Serviceorderfile_Current!$U523 -> 0 | BG4: =Serviceorderfile_PREVIOUS!$I523*Serviceorderfile_PREVIOUS!$U523 -> 0 | BH4: =IF(BG4>0,BF4/BG4-1,1) -> 1 | BI4: =BF4/N4 -> #DIV/0! | BJ4: =BG4/O4 -> #DIV/0! | BK4: =(BI4-BJ4)*100 -> #DIV/0! | BL4: =Serviceorderfile_Current!$I525*Serviceorderfile_Current!$U525 -> 16 | BM4: =Serviceorderfile_PREVIOUS!$I525*Serviceorderfile_PREVIOUS!$U525 -> 12 | BN4: =IF(BM4>0,BL4/BM4-1,1) -> 0.33333333 | BO4: =BL4/T4 -> 0.11347518 | BP4: =BM4/U4 -> 0.088888889 | BQ4: =(BO4-BP4)*100 -> 2.4586288 | BR4: =Serviceorderfile_Current!$I526*Serviceorderfile_Current!$U526 -> 4 | BS4: =Serviceorderfile_PREVIOUS!$I526*Serviceorderfile_PREVIOUS!$U526 -> 9 | BT4: =IF(BS4>0,BR4/BS4-1,1) -> -0.55555556 | BU4: =BR4/Z4 -> 1 | BV4: =BS4/AA4 -> 1 | BW4: =(BU4-BV4)*100 -> 0 | BX4: =Serviceorderfile_Current!$I520*Serviceorderfile_Current!$U520 -> 146 | BY4: =Serviceorderfile_PREVIOUS!$I520*Serviceorderfile_PREVIOUS!$U520 -> 206 | BZ4: =IF(BY4>0,BX4/BY4-1,1) -> -0.29126214 | CA4: =BX4/AF4 -> 0.49829352 | CB4: =BY4/AG4 -> 0.78625954 | CC4: =(CA4-CB4)*100 -> -28.796603 | CD4: =AT4+BL4+BR4+BX4+BF4 -> 184 | CE4: =AU4+BM4+BS4+BY4+BG4 -> 264 | CF4: =IF(CE4>0,CD4/CE4-1,1) -> -0.3030303 | CG4: =CD4/AL4 -> 0.36007828 | CH4: =CE4/AM4 -> 0.47567568 | CI4: =(CG4-CH4)*100 -> -11.55974 | CK4: IDA | CL4: =Serviceorderfile_Current!$J522*Serviceorderfile_Current!$U522 -> 55 | CM4: =Serviceorderfile_PREVIOUS!$J522*Serviceorderfile_PREVIOUS!$U522 -> 0 | CN4: =IF(CM4>0,CL4/CM4-1,1) -> 1 | CO4: =Serviceorderfile_Current!$J524*Serviceorderfile_Current!$U524 -> 0 | CP4: =Serviceorderfile_PREVIOUS!$J524*Serviceorderfile_PREVIOUS!$U524 -> 0 | CQ4: =IF(CP4>0,CO4/CP4-1,1) -> 1 | CR4: =Serviceorderfile_Current!$J523*Serviceorderfile_Current!$U523 -> 0 | CS4: =Serviceorderfile_PREVIOUS!$J523*Serviceorderfile_PREVIOUS!$U523 -> 0 | CT4: =IF(CS4>0,CR4/CS4-1,1) -> 1 | CU4: =Serviceorderfile_Current!$J525*Serviceorderfile_Current!$U525 -> 25 | CV4: =Serviceorderfile_PREVIOUS!$J525*Serviceorderfile_PREVIOUS!$U525 -> 29 | CW4: =IF(CV4>0,CU4/CV4-1,1) -> -0.13793103 | CX4: =Serviceorderfile_Current!$J526*Serviceorderfile_Current!$U526 -> 0 | CY4: =Serviceorderfile_PREVIOUS!$J526*Serviceorderfile_PREVIOUS!$U526 -> 0 | CZ4: =IF(CY4>0,CX4/CY4-1,1) -> 1 | DA4: =Serviceorderfile_Current!$J520*Serviceorderfile_Current!$U520 -> 98 | DB4: =Serviceorderfile_PREVIOUS!$J520*Serviceorderfile_PREVIOUS!$U520 -> 33 | DC4: =IF(DB4>0,DA4/DB4-1,1) -> 1.969697 | DD4: =CL4+CO4+CR4+CU4+CX4+DA4 -> 178 | DE4: =CM4+CP4+CS4+CV4+CY4+DB4 -> 62 | DF4: =IF(DE4>0,DD4/DE4-1,1) -> 1.8709677 | DH4: IDA | DI4: =Serviceorderfile_Current!$K522*Serviceorderfile_Current!$U522 -> 0 | DJ4: =Serviceorderfile_PREVIOUS!$K522*Serviceorderfile_PREVIOUS!$U522 -> 0 | DK4: =IF(DJ4>0,DI4/DJ4-1,1) -> 1 | DL4: =Serviceorderfile_Current!$K524*Serviceorderfile_Current!$U524 -> 0 | DM4: =Serviceorderfile_PREVIOUS!$K524*Serviceorderfile_PREVIOUS!$U524 -> 0 | DN4: =IF(DM4>0,DL4/DM4-1,1) -> 1 | DO4: =Serviceorderfile_Current!$K523*Serviceorderfile_Current!$U523 -> 0 | DP4: =Serviceorderfile_PREVIOUS!$K523*Serviceorderfile_PREVIOUS!$U523 -> 0 | DQ4: =IF(DP4>0,DO4/DP4-1,1) -> 1 | DR4: =Serviceorderfile_Current!$K525*Serviceorderfile_Current!$U525 -> 14 | DS4: =Serviceorderfile_PREVIOUS!$K525*Serviceorderfile_PREVIOUS!$U525 -> 12 | DT4: =IF(DS4>0,DR4/DS4-1,1) -> 0.16666667 | DU4: =Serviceorderfile_Current!$K526*Serviceorderfile_Current!$U526 -> 0 | DV4: =Serviceorderfile_PREVIOUS!$K526*Serviceorderfile_PREVIOUS!$U526 -> 0 | DW4: =IF(DV4>0,DU4/DV4-1,1) -> 1 | DX4: =Serviceorderfile_Current!$K520*Serviceorderfile_Current!$U520 -> 44 | DY4: =Serviceorderfile_PREVIOUS!$K520*Serviceorderfile_PREVIOUS!$U520 -> 23 | DZ4: =IF(DY4>0,DX4/DY4-1,1) -> 0.91304348 | EA4: =DI4+DL4+DO4+DR4+DU4+DX4 -> 58 | EB4: =DJ4+DM4+DP4+DS4+DV4+DY4 -> 35 | EC4: =IF(EB4>0,EA4/EB4-1,1) -> 0.65714286 | EE4: IDA | EF4: =Serviceorderfile_Current!$V519 -> 1 | EG4: =Aged!D32 -> 0 | EH4: =Serviceorderfile_Current!$U514*Serviceorderfile_Current!$H514 -> 0 | EI4: =Serviceorderfile_PREVIOUS!$U514*Serviceorderfile_PREVIOUS!$H514 -> 0 | EJ4: =IF(EI4>0,EH4/EI4-1,1) -> 1 | EK4: =Serviceorderfile_Current!$U516*Serviceorderfile_Current!$H516 -> 44 | EL4: =Serviceorderfile_PREVIOUS!$U516*Serviceorderfile_PREVIOUS!$H516 -> 0 | EM4: =IF(EL4>0,EK4/EL4-1,1) -> 1 | EN4: =Serviceorderfile_Current!$U515*Serviceorderfile_Current!$H515 -> 0 | EO4: =Serviceorderfile_PREVIOUS!$U515*Serviceorderfile_PREVIOUS!$H515 -> 0 | EP4: =IF(EO4>0,EN4/EO4-1,1) -> 1 | EQ4: =Serviceorderfile_Current!$U517*Serviceorderfile_Current!$H517 -> 120 | ER4: =Serviceorderfile_PREVIOUS!$U517*Serviceorderfile_PREVIOUS!$H517 -> 42 | ES4: =IF(ER4>0,EQ4/ER4-1,1) -> 1.8571429 | ET4: =Serviceorderfile_Current!$U518*Serviceorderfile_Current!$H518 -> 0 | EU4: =Serviceorderfile_PREVIOUS!$U518*Serviceorderfile_PREVIOUS!$H518 -> 0 | EV4: =IF(EU4>0,ET4/EU4-1,1) -> 1 | EX4: =Serviceorderfile_Current!$V512 -> 1 | EY4: =Aged!E85 -> 0.27 | EZ4: =Serviceorderfile_Current!$U516*Serviceorderfile_Current!$H516 -> 44 | FA4: =Serviceorderfile_PREVIOUS!$U516*Serviceorderfile_PREVIOUS!$H516 -> 0 | FB4: =IF(FA4>0,EZ4/FA4-1,1) -> 1 | FD4: =EZ4+ET4+EQ4+EN4+EK4+EH4 -> 208 | FE4: =FA4+EU4+ER4+EO4+EL4+EI4 -> 42 | FF4: =IF(FE4>0,FD4/FE4-1,1) -> 3.952381
A5: IDM | B5: =Serviceorderfile_Current!$W539 -> 58 | C5: =Serviceorderfile_PREVIOUS!$W539 -> 32 | D5: =IF(C5>0,B5/C5-1,1) -> 0.8125 | E5: ='YOY Orders'!$J18 -> 113 | F5: ='YOY Orders'!$B18 -> 118 | G5: =IF(F5>0,E5/F5-1,1) -> -0.042372881 | H5: =Serviceorderfile_Current!$W541 -> 0 | I5: =Serviceorderfile_PREVIOUS!$W541 -> 15 | J5: =IF(I5>0,H5/I5-1,1) -> -1 | K5: ='YOY Orders'!$K18 -> -15 | L5: ='YOY Orders'!$C18 -> 15 | M5: =IF(L5>0,K5/L5-1,1) -> -2 | N5: =Serviceorderfile_Current!$W540 -> 0 | O5: =Serviceorderfile_PREVIOUS!$W540 -> 0 | P5: =IF(O5>0,N5/O5-1,1) -> 1 | Q5: ='YOY Orders'!$O18 -> 0 | R5: ='YOY Orders'!$G18 -> 0 | S5: =IF(R5>0,Q5/R5-1,1) -> 1 | T5: =Serviceorderfile_Current!$W542 -> 237 | U5: =Serviceorderfile_PREVIOUS!$W542 -> 75 | V5: =IF(U5>0,T5/U5-1,1) -> 2.16 | W5: ='YOY Orders'!$L18 -> 330 | X5: ='YOY Orders'!$D18 -> 124 | Y5: =IF(X5>0,W5/X5-1,1) -> 1.6612903 | Z5: =Serviceorderfile_Current!$W543 -> 0 | AA5: =Serviceorderfile_PREVIOUS!$W543 -> 3 | AB5: =IF(AA5>0,Z5/AA5-1,1) -> -1 | AC5: ='YOY Orders'!$N18 -> 0 | AD5: ='YOY Orders'!$F18 -> 3 | AE5: =IF(AD5>0,AC5/AD5-1,1) -> -1 | AF5: =Serviceorderfile_Current!$W537 -> 95 | AG5: =Serviceorderfile_PREVIOUS!$W537 -> 35 | AH5: =IF(AG5>0,AF5/AG5-1,1) -> 1.7142857 | AI5: ='YOY Orders'!$M18 -> 185 | AJ5: ='YOY Orders'!$E18 -> 89 | AK5: =IF(AJ5>0,AI5/AJ5-1,1) -> 1.0786517 | AL5: =B5+T5+Z5+AF5+N5+H5 -> 390 | AM5: =C5+U5+AA5+AG5+O5+I5 -> 160 | AN5: =IF(AM5>0,AL5/AM5-1,1) -> 1.4375 | AO5: =E5+W5+AC5+AI5+Q5+K5 -> 613 | AP5: =F5+X5+AD5+AJ5+R5+L5 -> 349 | AQ5: =IF(AP5>0,AO5/AP5-1,1) -> 0.75644699 | AS5: IDM | AT5: =Serviceorderfile_Current!$I539*Serviceorderfile_Current!$U539 -> 15 | AU5: =Serviceorderfile_PREVIOUS!$I539*Serviceorderfile_PREVIOUS!$U539 -> 32 | AV5: =IF(AU5>0,AT5/AU5-1,1) -> -0.53125 | AW5: =AT5/B5 -> 0.25862069 | AX5: =AU5/C5 -> 1 | AY5: =(AW5-AX5)*100 -> -74.137931 | AZ5: =Serviceorderfile_Current!$I541*Serviceorderfile_Current!$U541 -> 0 | BA5: =Serviceorderfile_PREVIOUS!$I541*Serviceorderfile_PREVIOUS!$U541 -> 0 | BB5: =IF(BA5>0,AZ5/BA5-1,1) -> 1 | BC5: =AZ5/H5 -> #DIV/0! | BD5: =BA5/I5 -> 0 | BE5: =(BC5-BD5)*100 -> #DIV/0! | BF5: =Serviceorderfile_Current!$I540*Serviceorderfile_Current!$U540 -> 0 | BG5: =Serviceorderfile_PREVIOUS!$I540*Serviceorderfile_PREVIOUS!$U540 -> 0 | BH5: =IF(BG5>0,BF5/BG5-1,1) -> 1 | BI5: =BF5/N5 -> #DIV/0! | BJ5: =BG5/O5 -> #DIV/0! | BK5: =(BI5-BJ5)*100 -> #DIV/0! | BL5: =Serviceorderfile_Current!$I542*Serviceorderfile_Current!$U542 -> 26 | BM5: =Serviceorderfile_PREVIOUS!$I542*Serviceorderfile_PREVIOUS!$U542 -> 34 | BN5: =IF(BM5>0,BL5/BM5-1,1) -> -0.23529412 | BO5: =BL5/T5 -> 0.10970464 | BP5: =BM5/U5 -> 0.45333333 | BQ5: =(BO5-BP5)*100 -> -34.362869 | BR5: =Serviceorderfile_Current!$I543*Serviceorderfile_Current!$U543 -> 0 | BS5: =Serviceorderfile_PREVIOUS!$I543*Serviceorderfile_PREVIOUS!$U543 -> 3 | BT5: =IF(BS5>0,BR5/BS5-1,1) -> -1 | BU5: =BR5/Z5 -> #DIV/0! | BV5: =BS5/AA5 -> 1 | BW5: =(BU5-BV5)*100 -> #DIV/0! | BX5: =Serviceorderfile_Current!$I537*Serviceorderfile_Current!$U537 -> 14 | BY5: =Serviceorderfile_PREVIOUS!$I537*Serviceorderfile_PREVIOUS!$U537 -> 9 | BZ5: =IF(BY5>0,BX5/BY5-1,1) -> 0.55555556 | CA5: =BX5/AF5 -> 0.14736842 | CB5: =BY5/AG5 -> 0.25714286 | CC5: =(CA5-CB5)*100 -> -10.977444 | CD5: =AT5+BL5+BR5+BX5+BF5 -> 55 | CE5: =AU5+BM5+BS5+BY5+BG5 -> 78 | CF5: =IF(CE5>0,CD5/CE5-1,1) -> -0.29487179 | CG5: =CD5/AL5 -> 0.14102564 | CH5: =CE5/AM5 -> 0.4875 | CI5: =(CG5-CH5)*100 -> -34.647436 | CK5: IDM | CL5: =Serviceorderfile_Current!$J539*Serviceorderfile_Current!$U539 -> 40 | CM5: =Serviceorderfile_PREVIOUS!$J539*Serviceorderfile_PREVIOUS!$U539 -> 0 | CN5: =IF(CM5>0,CL5/CM5-1,1) -> 1 | CO5: =Serviceorderfile_Current!$J541*Serviceorderfile_Current!$U541 -> 0 | CP5: =Serviceorderfile_PREVIOUS!$J541*Serviceorderfile_PREVIOUS!$U541 -> 0 | CQ5: =IF(CP5>0,CO5/CP5-1,1) -> 1 | CR5: =Serviceorderfile_Current!$J540*Serviceorderfile_Current!$U540 -> 0 | CS5: =Serviceorderfile_PREVIOUS!$J540*Serviceorderfile_PREVIOUS!$U540 -> 0 | CT5: =IF(CS5>0,CR5/CS5-1,1) -> 1 | CU5: =Serviceorderfile_Current!$J542*Serviceorderfile_Current!$U542 -> 26 | CV5: =Serviceorderfile_PREVIOUS!$J542*Serviceorderfile_PREVIOUS!$U542 -> 31 | CW5: =IF(CV5>0,CU5/CV5-1,1) -> -0.16129032 | CX5: =Serviceorderfile_Current!$J543*Serviceorderfile_Current!$U543 -> 0 | CY5: =Serviceorderfile_PREVIOUS!$J543*Serviceorderfile_PREVIOUS!$U543 -> 0 | CZ5: =IF(CY5>0,CX5/CY5-1,1) -> 1 | DA5: =Serviceorderfile_Current!$J537*Serviceorderfile_Current!$U537 -> 0 | DB5: =Serviceorderfile_PREVIOUS!$J537*Serviceorderfile_PREVIOUS!$U537 -> 26 | DC5: =IF(DB5>0,DA5/DB5-1,1) -> -1 | DD5: =CL5+CO5+CR5+CU5+CX5+DA5 -> 66 | DE5: =CM5+CP5+CS5+CV5+CY5+DB5 -> 57 | DF5: =IF(DE5>0,DD5/DE5-1,1) -> 0.15789474 | DH5: IDM | DI5: =Serviceorderfile_Current!$K539*Serviceorderfile_Current!$U539 -> 0 | DJ5: =Serviceorderfile_PREVIOUS!$K539*Serviceorderfile_PREVIOUS!$U539 -> 0 | DK5: =IF(DJ5>0,DI5/DJ5-1,1) -> 1 | DL5: =Serviceorderfile_Current!$K541*Serviceorderfile_Current!$U541 -> 0 | DM5: =Serviceorderfile_PREVIOUS!$K541*Serviceorderfile_PREVIOUS!$U541 -> 0 | DN5: =IF(DM5>0,DL5/DM5-1,1) -> 1 | DO5: =Serviceorderfile_Current!$K540*Serviceorderfile_Current!$U540 -> 0 | DP5: =Serviceorderfile_PREVIOUS!$K540*Serviceorderfile_PREVIOUS!$U540 -> 0 | DQ5: =IF(DP5>0,DO5/DP5-1,1) -> 1 | DR5: =Serviceorderfile_Current!$K542*Serviceorderfile_Current!$U542 -> 26 | DS5: =Serviceorderfile_PREVIOUS!$K542*Serviceorderfile_PREVIOUS!$U542 -> 1 | DT5: =IF(DS5>0,DR5/DS5-1,1) -> 25 | DU5: =Serviceorderfile_Current!$K543*Serviceorderfile_Current!$U543 -> 0 | DV5: =Serviceorderfile_PREVIOUS!$K543*Serviceorderfile_PREVIOUS!$U543 -> 0 | DW5: =IF(DV5>0,DU5/DV5-1,1) -> 1 | DX5: =Serviceorderfile_Current!$K537*Serviceorderfile_Current!$U537 -> 1 | DY5: =Serviceorderfile_PREVIOUS!$K537*Serviceorderfile_PREVIOUS!$U537 -> 0 | DZ5: =IF(DY5>0,DX5/DY5-1,1) -> 1 | EA5: =DI5+DL5+DO5+DR5+DU5+DX5 -> 27 | EB5: =DJ5+DM5+DP5+DS5+DV5+DY5 -> 1 | EC5: =IF(EB5>0,EA5/EB5-1,1) -> 26 | EE5: IDM | EF5: =Serviceorderfile_Current!$V536 -> #DIV/0! | EG5: =Aged!E33 -> 0 | EH5: =Serviceorderfile_Current!$U531*Serviceorderfile_Current!$H531 -> 0 | EI5: =Serviceorderfile_PREVIOUS!$U531*Serviceorderfile_PREVIOUS!$H531 -> 103 | EJ5: =IF(EI5>0,EH5/EI5-1,1) -> -1 | EK5: =Serviceorderfile_Current!$U533*Serviceorderfile_Current!$H533 -> 0 | EL5: =Serviceorderfile_PREVIOUS!$U533*Serviceorderfile_PREVIOUS!$H533 -> 0 | EM5: =IF(EL5>0,EK5/EL5-1,1) -> 1 | EN5: =Serviceorderfile_Current!$U532*Serviceorderfile_Current!$H532 -> 0 | EO5: =Serviceorderfile_PREVIOUS!$U532*Serviceorderfile_PREVIOUS!$H532 -> 0 | EP5: =IF(EO5>0,EN5/EO5-1,1) -> 1 | EQ5: =Serviceorderfile_Current!$U534*Serviceorderfile_Current!$H534 -> 0 | ER5: =Serviceorderfile_PREVIOUS!$U534*Serviceorderfile_PREVIOUS!$H534 -> 0 | ES5: =IF(ER5>0,EQ5/ER5-1,1) -> 1 | ET5: =Serviceorderfile_Current!$U535*Serviceorderfile_Current!$H535 -> 0 | EU5: =Serviceorderfile_PREVIOUS!$U535*Serviceorderfile_PREVIOUS!$H535 -> 0 | EV5: =IF(EU5>0,ET5/EU5-1,1) -> 1 | EX5: =Serviceorderfile_Current!$V529 -> #DIV/0! | EY5: =Aged!E86 -> 0 | EZ5: =Serviceorderfile_Current!$U533*Serviceorderfile_Current!$H533 -> 0 | FA5: =Serviceorderfile_PREVIOUS!$U533*Serviceorderfile_PREVIOUS!$H533 -> 0 | FB5: =IF(FA5>0,EZ5/FA5-1,1) -> 1 | FD5: =EZ5+ET5+EQ5+EN5+EK5+EH5 -> 0 | FE5: =FA5+EU5+ER5+EO5+EL5+EI5 -> 103 | FF5: =IF(FE5>0,FD5/FE5-1,1) -> -1
A6: IDS | B6: =Serviceorderfile_Current!$W556 -> 0 | C6: =Serviceorderfile_PREVIOUS!$W556 -> 0 | D6: =IF(C6>0,B6/C6-1,1) -> 1 | E6: ='YOY Orders'!$J37 -> 0 | F6: ='YOY Orders'!$B37 -> 0 | G6: =IF(F6>0,E6/F6-1,1) -> 1 | H6: =Serviceorderfile_Current!$W558 -> 0 | I6: =Serviceorderfile_PREVIOUS!$W558 -> 0 | J6: =IF(I6>0,H6/I6-1,1) -> 1 | K6: ='YOY Orders'!$K37 -> 0 | L6: ='YOY Orders'!$C38 -> 0 | M6: =IF(L6>0,K6/L6-1,1) -> 1 | N6: =Serviceorderfile_Current!$W557 -> 0 | O6: =Serviceorderfile_PREVIOUS!$W557 -> 0 | P6: =IF(O6>0,N6/O6-1,1) -> 1 | Q6: ='YOY Orders'!$O37 -> 0 | R6: ='YOY Orders'!$G37 -> 0 | S6: =IF(R6>0,Q6/R6-1,1) -> 1 | T6: =Serviceorderfile_Current!$W559 -> 0 | U6: =Serviceorderfile_PREVIOUS!$W559 -> 0 | V6: =IF(U6>0,T6/U6-1,1) -> 1 | W6: ='YOY Orders'!$L37 -> 0 | X6: ='YOY Orders'!$D37 -> 0 | Y6: =IF(X6>0,W6/X6-1,1) -> 1 | Z6: =Serviceorderfile_Current!$W560 -> 0 | AA6: =Serviceorderfile_PREVIOUS!$W560 -> 0 | AB6: =IF(AA6>0,Z6/AA6-1,1) -> 1 | AC6: ='YOY Orders'!$N37 -> 0 | AD6: ='YOY Orders'!$F37 -> 0 | AE6: =IF(AD6>0,AC6/AD6-1,1) -> 1 | AF6: =Serviceorderfile_Current!$W554 -> 109.01537 | AG6: =Serviceorderfile_PREVIOUS!$W554 -> 61.304487 | AH6: =IF(AG6>0,AF6/AG6-1,1) -> 0.77826087 | AI6: ='YOY Orders'!$M37 -> 193.24241 | AJ6: ='YOY Orders'!$E37 -> 191.64316 | AK6: =IF(AJ6>0,AI6/AJ6-1,1) -> 0.0083449235 | AL6: =B6+T6+Z6+AF6+N6+H6 -> 109.01537 | AM6: =C6+U6+AA6+AG6+O6+I6 -> 61.304487 | AN6: =IF(AM6>0,AL6/AM6-1,1) -> 0.77826087 | AO6: =E6+W6+AC6+AI6+Q6+K6 -> 193.24241 | AP6: =F6+X6+AD6+AJ6+R6+L6 -> 191.64316 | AQ6: =IF(AP6>0,AO6/AP6-1,1) -> 0.0083449235 | AS6: IDS | AT6: =Serviceorderfile_Current!$I556*Serviceorderfile_Current!$U556 -> 0 | AU6: =Serviceorderfile_PREVIOUS!$I556*Serviceorderfile_PREVIOUS!$U556 -> 0 | AV6: =IF(AU6>0,AT6/AU6-1,1) -> 1 | AW6: =AT6/B6 -> #DIV/0! | AX6: =AU6/C6 -> #DIV/0! | AY6: =(AW6-AX6)*100 -> #DIV/0! | AZ6: =Serviceorderfile_Current!$I558*Serviceorderfile_Current!$U558 -> 0 | BA6: =Serviceorderfile_PREVIOUS!$I558*Serviceorderfile_PREVIOUS!$U558 -> 0 | BB6: =IF(BA6>0,AZ6/BA6-1,1) -> 1 | BC6: =AZ6/H6 -> #DIV/0! | BD6: =BA6/I6 -> #DIV/0! | BE6: =(BC6-BD6)*100 -> #DIV/0! | BF6: =Serviceorderfile_Current!$I557*Serviceorderfile_Current!$U557 -> 0 | BG6: =Serviceorderfile_PREVIOUS!$I557*Serviceorderfile_PREVIOUS!$U557 -> 0 | BH6: =IF(BG6>0,BF6/BG6-1,1) -> 1 | BI6: =BF6/N6 -> #DIV/0! | BJ6: =BG6/O6 -> #DIV/0! | BK6: =(BI6-BJ6)*100 -> #DIV/0! | BL6: =Serviceorderfile_Current!$I559*Serviceorderfile_Current!$U559 -> 0 | BM6: =Serviceorderfile_PREVIOUS!$I559*Serviceorderfile_PREVIOUS!$U559 -> 0 | BN6: =IF(BM6>0,BL6/BM6-1,1) -> 1 | BO6: =BL6/T6 -> #DIV/0! | BP6: =BM6/U6 -> #DIV/0! | BQ6: =(BO6-BP6)*100 -> #DIV/0! | BR6: =Serviceorderfile_Current!$I560*Serviceorderfile_Current!$U560 -> 0 | BS6: =Serviceorderfile_PREVIOUS!$I560*Serviceorderfile_PREVIOUS!$U560 -> 0 | BT6: =IF(BS6>0,BR6/BS6-1,1) -> 1 | BU6: =BR6/Z6 -> #DIV/0! | BV6: =BS6/AA6 -> #DIV/0! | BW6: =(BU6-BV6)*100 -> #DIV/0! | BX6: =Serviceorderfile_Current!$I554*Serviceorderfile_Current!$U554 -> 51.17592 | BY6: =Serviceorderfile_PREVIOUS!$I554*Serviceorderfile_PREVIOUS!$U554 -> 47.710884 | BZ6: =IF(BY6>0,BX6/BY6-1,1) -> 0.072625698 | CA6: =BX6/AF6 -> 0.46943765 | CB6: =BY6/AG6 -> 0.77826087 | CC6: =(CA6-CB6)*100 -> -30.882322 | CD6: =AT6+BL6+BR6+BX6+BF6 -> 51.17592 | CE6: =AU6+BM6+BS6+BY6+BG6 -> 47.710884 | CF6: =IF(CE6>0,CD6/CE6-1,1) -> 0.072625698 | CG6: =CD6/AL6 -> 0.46943765 | CH6: =CE6/AM6 -> 0.77826087 | CI6: =(CG6-CH6)*100 -> -30.882322 | CK6: IDS | CL6: =Serviceorderfile_Current!$J556*Serviceorderfile_Current!$U556 -> 0 | CM6: =Serviceorderfile_PREVIOUS!$J556*Serviceorderfile_PREVIOUS!$U556 -> 0 | CN6: =IF(CM6>0,CL6/CM6-1,1) -> 1 | CO6: =Serviceorderfile_Current!$J558*Serviceorderfile_Current!$U558 -> 0 | CP6: =Serviceorderfile_PREVIOUS!$J558*Serviceorderfile_PREVIOUS!$U558 -> 0 | CQ6: =IF(CP6>0,CO6/CP6-1,1) -> 1 | CR6: =Serviceorderfile_Current!$J557*Serviceorderfile_Current!$U557 -> 0 | CS6: =Serviceorderfile_PREVIOUS!$J557*Serviceorderfile_PREVIOUS!$U557 -> 0 | CT6: =IF(CS6>0,CR6/CS6-1,1) -> 1 | CU6: =Serviceorderfile_Current!$J559*Serviceorderfile_Current!$U559 -> 0 | CV6: =Serviceorderfile_PREVIOUS!$J559*Serviceorderfile_PREVIOUS!$U559 -> 0 | CW6: =IF(CV6>0,CU6/CV6-1,1) -> 1 | CX6: =Serviceorderfile_Current!$J560*Serviceorderfile_Current!$U560 -> 0 | CY6: =Serviceorderfile_PREVIOUS!$J560*Serviceorderfile_PREVIOUS!$U560 -> 0 | CZ6: =IF(CY6>0,CX6/CY6-1,1) -> 1 | DA6: =Serviceorderfile_Current!$J554*Serviceorderfile_Current!$U554 -> 1.8657887 | DB6: =Serviceorderfile_PREVIOUS!$J554*Serviceorderfile_PREVIOUS!$U554 -> 4.26466 | DC6: =IF(DB6>0,DA6/DB6-1,1) -> -0.5625 | DD6: =CL6+CO6+CR6+CU6+CX6+DA6 -> 1.8657887 | DE6: =CM6+CP6+CS6+CV6+CY6+DB6 -> 4.26466 | DF6: =IF(DE6>0,DD6/DE6-1,1) -> -0.5625 | DH6: IDS | DI6: =Serviceorderfile_Current!$K556*Serviceorderfile_Current!$U556 -> 0 | DJ6: =Serviceorderfile_PREVIOUS!$K556*Serviceorderfile_PREVIOUS!$U556 -> 0 | DK6: =IF(DJ6>0,DI6/DJ6-1,1) -> 1 | DL6: =Serviceorderfile_Current!$K558*Serviceorderfile_Current!$U558 -> 0 | DM6: =Serviceorderfile_PREVIOUS!$K558*Serviceorderfile_PREVIOUS!$U558 -> 0 | DN6: =IF(DM6>0,DL6/DM6-1,1) -> 1 | DO6: =Serviceorderfile_Current!$K557*Serviceorderfile_Current!$U557 -> 0 | DP6: =Serviceorderfile_PREVIOUS!$K557*Serviceorderfile_PREVIOUS!$U557 -> 0 | DQ6: =IF(DP6>0,DO6/DP6-1,1) -> 1 | DR6: =Serviceorderfile_Current!$K559*Serviceorderfile_Current!$U559 -> 0 | DS6: =Serviceorderfile_PREVIOUS!$K559*Serviceorderfile_PREVIOUS!$U559 -> 0 | DT6: =IF(DS6>0,DR6/DS6-1,1) -> 1 | DU6: =Serviceorderfile_Current!$K560*Serviceorderfile_Current!$U560 -> 0 | DV6: =Serviceorderfile_PREVIOUS!$K560*Serviceorderfile_PREVIOUS!$U560 -> 0 | DW6: =IF(DV6>0,DU6/DV6-1,1) -> 1 | DX6: =Serviceorderfile_Current!$K554*Serviceorderfile_Current!$U554 -> 7.463155 | DY6: =Serviceorderfile_PREVIOUS!$K554*Serviceorderfile_PREVIOUS!$U554 -> 9.3289437 | DZ6: =IF(DY6>0,DX6/DY6-1,1) -> -0.2 | EA6: =DI6+DL6+DO6+DR6+DU6+DX6 -> 7.463155 | EB6: =DJ6+DM6+DP6+DS6+DV6+DY6 -> 9.3289437 | EC6: =IF(EB6>0,EA6/EB6-1,1) -> -0.2 | EE6: IDS | EF6: =Serviceorderfile_Current!$V553 -> #DIV/0! | EG6: =Aged!E34 -> 0 | EH6: =Serviceorderfile_Current!$U548*Serviceorderfile_Current!$H548 -> 0 | EI6: =Serviceorderfile_PREVIOUS!$U548*Serviceorderfile_PREVIOUS!$H548 -> 0 | EJ6: =IF(EI6>0,EH6/EI6-1,1) -> 1 | EK6: =Serviceorderfile_Current!$U550*Serviceorderfile_Current!$H550 -> 0 | EL6: =Serviceorderfile_PREVIOUS!$U550*Serviceorderfile_PREVIOUS!$H550 -> 0 | EM6: =IF(EL6>0,EK6/EL6-1,1) -> 1 | EN6: =Serviceorderfile_Current!$U549*Serviceorderfile_Current!$H549 -> 0 | EO6: =Serviceorderfile_PREVIOUS!$U549*Serviceorderfile_PREVIOUS!$H549 -> 0 | EP6: =IF(EO6>0,EN6/EO6-1,1) -> 1 | EQ6: =Serviceorderfile_Current!$U551*Serviceorderfile_Current!$H551 -> 0 | ER6: =Serviceorderfile_PREVIOUS!$U551*Serviceorderfile_PREVIOUS!$H551 -> 0 | ES6: =IF(ER6>0,EQ6/ER6-1,1) -> 1 | ET6: =Serviceorderfile_Current!$U552*Serviceorderfile_Current!$H552 -> 0 | EU6: =Serviceorderfile_PREVIOUS!$U552*Serviceorderfile_PREVIOUS!$H552 -> 0 | EV6: =IF(EU6>0,ET6/EU6-1,1) -> 1 | EX6: =Serviceorderfile_Current!$V546 -> #DIV/0! | EY6: =Aged!E87 -> 0 | EZ6: =Serviceorderfile_Current!$U550*Serviceorderfile_Current!$H550 -> 0 | FA6: =Serviceorderfile_PREVIOUS!$U550*Serviceorderfile_PREVIOUS!$H550 -> 0 | FB6: =IF(FA6>0,EZ6/FA6-1,1) -> 1 | FD6: =EZ6+ET6+EQ6+EN6+EK6+EH6 -> 0 | FE6: =FA6+EU6+ER6+EO6+EL6+EI6 -> 0 | FF6: =IF(FE6>0,FD6/FE6-1,1) -> 1
A7: Saudi | B7: =Serviceorderfile_Current!$W692 -> 340.90626 | C7: =Serviceorderfile_PREVIOUS!$W692 -> 605.04864 | D7: =IF(C7>0,B7/C7-1,1) -> -0.43656388 | E7: ='YOY Orders'!$J31 -> 715.39671 | F7: ='YOY Orders'!$B31 -> 959.28196 | G7: =IF(F7>0,E7/F7-1,1) -> -0.25423729 | H7: =Serviceorderfile_Current!$W694 -> 711.66513 | I7: =Serviceorderfile_PREVIOUS!$W694 -> 425.66637 | J7: =IF(I7>0,H7/I7-1,1) -> 0.67188478 | K7: ='YOY Orders'!$K31 -> 872.12297 | L7: ='YOY Orders'!$C31 -> -15.459392 | M7: =IF(L7>0,K7/L7-1,1) -> 1 | N7: =Serviceorderfile_Current!$W693 -> 1622.7031 | O7: =Serviceorderfile_PREVIOUS!$W693 -> 1665.0832 | P7: =IF(O7>0,N7/O7-1,1) -> -0.025452217 | Q7: ='YOY Orders'!$O31 -> 2779.2256 | R7: ='YOY Orders'!$G31 -> 2229.0845 | S7: =IF(R7>0,Q7/R7-1,1) -> 0.24680139 | T7: =Serviceorderfile_Current!$W695 -> 557.07121 | U7: =Serviceorderfile_PREVIOUS!$W695 -> 493.63439 | V7: =IF(U7>0,T7/U7-1,1) -> 0.12850972 | W7: ='YOY Orders'!$L31 -> 614.64412 | X7: ='YOY Orders'!$D31 -> 391.01601 | Y7: =IF(X7>0,W7/X7-1,1) -> 0.57191547 | Z7: =Serviceorderfile_Current!$W696 -> 63.9699 | AA7: =Serviceorderfile_PREVIOUS!$W696 -> 103.418 | AB7: =IF(AA7>0,Z7/AA7-1,1) -> -0.3814433 | AC7: ='YOY Orders'!$N31 -> 93.82252 | AD7: ='YOY Orders'!$F31 -> 124.47476 | AE7: =IF(AD7>0,AC7/AD7-1,1) -> -0.24625268 | AF7: =Serviceorderfile_Current!$W690 -> 0 | AG7: =Serviceorderfile_PREVIOUS!$W690 -> 0 | AH7: =IF(AG7>0,AF7/AG7-1,1) -> 1 | AI7: ='YOY Orders'!$M31 -> 0 | AJ7: ='YOY Orders'!$E31 -> 0 | AK7: =IF(AJ7>0,AI7/AJ7-1,1) -> 1 | AL7: =B7+T7+Z7+AF7+N7+H7 -> 3296.3156 | AM7: =C7+U7+AA7+AG7+O7+I7 -> 3292.8506 | AN7: =IF(AM7>0,AL7/AM7-1,1) -> 0.0010522908 | AO7: =E7+W7+AC7+AI7+Q7+K7 -> 5075.2119 | AP7: =F7+X7+AD7+AJ7+R7+L7 -> 3688.3978 | AQ7: =IF(AP7>0,AO7/AP7-1,1) -> 0.37599364 | AS7: Saudi | AT7: =Serviceorderfile_Current!$I692*Serviceorderfile_Current!$U692 -> 139.13453 | AU7: =Serviceorderfile_PREVIOUS!$I692*Serviceorderfile_PREVIOUS!$U692 -> 246.55066 | AV7: =IF(AU7>0,AT7/AU7-1,1) -> -0.43567568 | AW7: =AT7/B7 -> 0.40813135 | AX7: =AU7/C7 -> 0.40748899 | AY7: =(AW7-AX7)*100 -> 0.064236584 | AZ7: =Serviceorderfile_Current!$I694*Serviceorderfile_Current!$U694 -> 142.59957 | BA7: =Serviceorderfile_PREVIOUS!$I694*Serviceorderfile_PREVIOUS!$U694 -> 269.4732 | BB7: =IF(BA7>0,AZ7/BA7-1,1) -> -0.47082097 | BC7: =AZ7/H7 -> 0.20037453 | BD7: =BA7/I7 -> 0.63306199 | BE7: =(BC7-BD7)*100 -> -43.268746 | BF7: =Serviceorderfile_Current!$I693*Serviceorderfile_Current!$U693 -> 526.15243 | BG7: =Serviceorderfile_PREVIOUS!$I693*Serviceorderfile_PREVIOUS!$U693 -> 621.04111 | BH7: =IF(BG7>0,BF7/BG7-1,1) -> -0.1527897 | BI7: =BF7/N7 -> 0.32424442 | BJ7: =BG7/O7 -> 0.37297903 | BK7: =(BI7-BJ7)*100 -> -4.8734615 | BL7: =Serviceorderfile_Current!$I695*Serviceorderfile_Current!$U695 -> 78.89621 | BM7: =Serviceorderfile_PREVIOUS!$I695*Serviceorderfile_PREVIOUS!$U695 -> 73.032302 | BN7: =IF(BM7>0,BL7/BM7-1,1) -> 0.080291971 | BO7: =BL7/T7 -> 0.14162679 | BP7: =BM7/U7 -> 0.14794816 | BQ7: =(BO7-BP7)*100 -> -0.63213699 | BR7: =Serviceorderfile_Current!$I696*Serviceorderfile_Current!$U696 -> 3.7315775 | BS7: =Serviceorderfile_PREVIOUS!$I696*Serviceorderfile_PREVIOUS!$U696 -> 37.049234 | BT7: =IF(BS7>0,BR7/BS7-1,1) -> -0.89928058 | BU7: =BR7/Z7 -> 0.058333333 | BV7: =BS7/AA7 -> 0.35824742 | BW7: =(BU7-BV7)*100 -> -29.991409 | BX7: =Serviceorderfile_Current!$I690*Serviceorderfile_Current!$U690 -> 0 | BY7: =Serviceorderfile_PREVIOUS!$I690*Serviceorderfile_PREVIOUS!$U690 -> 0 | BZ7: =IF(BY7>0,BX7/BY7-1,1) -> 1 | CA7: =BX7/AF7 -> #DIV/0! | CB7: =BY7/AG7 -> #DIV/0! | CC7: =(CA7-CB7)*100 -> #DIV/0! | CD7: =AT7+BL7+BR7+BX7+BF7 -> 747.91474 | CE7: =AU7+BM7+BS7+BY7+BG7 -> 977.6733 | CF7: =IF(CE7>0,CD7/CE7-1,1) -> -0.23500545 | CG7: =CD7/AL7 -> 0.22689415 | CH7: =CE7/AM7 -> 0.29690788 | CI7: =(CG7-CH7)*100 -> -7.001373 | CK7: Saudi | CL7: =Serviceorderfile_Current!$J692*Serviceorderfile_Current!$U692 -> 77.030421 | CM7: =Serviceorderfile_PREVIOUS!$J692*Serviceorderfile_PREVIOUS!$U692 -> 55.973662 | CN7: =IF(CM7>0,CL7/CM7-1,1) -> 0.37619048 | CO7: =Serviceorderfile_Current!$J694*Serviceorderfile_Current!$U694 -> 84.227035 | CP7: =Serviceorderfile_PREVIOUS!$J694*Serviceorderfile_PREVIOUS!$U694 -> 156.19317 | CQ7: =IF(CP7>0,CO7/CP7-1,1) -> -0.46075085 | CR7: =Serviceorderfile_Current!$J693*Serviceorderfile_Current!$U693 -> 289.99688 | CS7: =Serviceorderfile_PREVIOUS!$J693*Serviceorderfile_PREVIOUS!$U693 -> 347.30325 | CT7: =IF(CS7>0,CR7/CS7-1,1) -> -0.16500384 | CU7: =Serviceorderfile_Current!$J695*Serviceorderfile_Current!$U695 -> 70.633431 | CV7: =Serviceorderfile_PREVIOUS!$J695*Serviceorderfile_PREVIOUS!$U695 -> 67.701477 | CW7: =IF(CV7>0,CU7/CV7-1,1) -> 0.043307087 | CX7: =Serviceorderfile_Current!$J696*Serviceorderfile_Current!$U696 -> 22.122924 | CY7: =Serviceorderfile_PREVIOUS!$J696*Serviceorderfile_PREVIOUS!$U696 -> 28.786455 | CZ7: =IF(CY7>0,CX7/CY7-1,1) -> -0.23148148 | DA7: =Serviceorderfile_Current!$J690*Serviceorderfile_Current!$U690 -> 0 | DB7: =Serviceorderfile_PREVIOUS!$J690*Serviceorderfile_PREVIOUS!$U690 -> 0 | DC7: =IF(DB7>0,DA7/DB7-1,1) -> 1 | DD7: =CL7+CO7+CR7+CU7+CX7+DA7 -> 544.01069 | DE7: =CM7+CP7+CS7+CV7+CY7+DB7 -> 655.95801 | DF7: =IF(DE7>0,DD7/DE7-1,1) -> -0.17066233 | DH7: Saudi | DI7: =Serviceorderfile_Current!$K692*Serviceorderfile_Current!$U692 -> 11.194732 | DJ7: =Serviceorderfile_PREVIOUS!$K692*Serviceorderfile_PREVIOUS!$U692 -> 73.032302 | DK7: =IF(DJ7>0,DI7/DJ7-1,1) -> -0.84671533 | DL7: =Serviceorderfile_Current!$K694*Serviceorderfile_Current!$U694 -> 264.942 | DM7: =Serviceorderfile_PREVIOUS!$K694*Serviceorderfile_PREVIOUS!$U694 -> 0 | DN7: =IF(DM7>0,DL7/DM7-1,1) -> 1 | DO7: =Serviceorderfile_Current!$K693*Serviceorderfile_Current!$U693 -> 180.18188 | DP7: =Serviceorderfile_PREVIOUS!$K693*Serviceorderfile_PREVIOUS!$U693 -> 94.355602 | DQ7: =IF(DP7>0,DO7/DP7-1,1) -> 0.90960452 | DR7: =Serviceorderfile_Current!$K695*Serviceorderfile_Current!$U695 -> 64.502982 | DS7: =Serviceorderfile_PREVIOUS!$K695*Serviceorderfile_PREVIOUS!$U695 -> 70.899972 | DT7: =IF(DS7>0,DR7/DS7-1,1) -> -0.090225564 | DU7: =Serviceorderfile_Current!$K696*Serviceorderfile_Current!$U696 -> 5.8639075 | DV7: =Serviceorderfile_PREVIOUS!$K696*Serviceorderfile_PREVIOUS!$U696 -> 9.3289437 | DW7: =IF(DV7>0,DU7/DV7-1,1) -> -0.37142857 | DX7: =Serviceorderfile_Current!$K690*Serviceorderfile_Current!$U690 -> 0 | DY7: =Serviceorderfile_PREVIOUS!$K690*Serviceorderfile_PREVIOUS!$U690 -> 0 | DZ7: =IF(DY7>0,DX7/DY7-1,1) -> 1 | EA7: =DI7+DL7+DO7+DR7+DU7+DX7 -> 526.68551 | EB7: =DJ7+DM7+DP7+DS7+DV7+DY7 -> 247.61682 | EC7: =IF(EB7>0,EA7/EB7-1,1) -> 1.1270183 | EE7: Saudi | EF7: =Serviceorderfile_Current!$V689 -> 0.98257667 | EG7: =Aged!E42 -> 0.97 | EH7: =Serviceorderfile_Current!$U684*Serviceorderfile_Current!$H684 -> 308.92131 | EI7: =Serviceorderfile_PREVIOUS!$U684*Serviceorderfile_PREVIOUS!$H684 -> 630.10351 | EJ7: =IF(EI7>0,EH7/EI7-1,1) -> -0.50972927 | EK7: =Serviceorderfile_Current!$U686*Serviceorderfile_Current!$H686 -> 1401.4739 | EL7: =Serviceorderfile_PREVIOUS!$U686*Serviceorderfile_PREVIOUS!$H686 -> 868.39139 | EM7: =IF(EL7>0,EK7/EL7-1,1) -> 0.61387354 | EN7: =Serviceorderfile_Current!$U685*Serviceorderfile_Current!$H685 -> 6838.3823 | EO7: =Serviceorderfile_PREVIOUS!$U685*Serviceorderfile_PREVIOUS!$H685 -> 2955.6759 | EP7: =IF(EO7>0,EN7/EO7-1,1) -> 1.3136442 | EQ7: =Serviceorderfile_Current!$U687*Serviceorderfile_Current!$H687 -> 63.9699 | ER7: =Serviceorderfile_PREVIOUS!$U687*Serviceorderfile_PREVIOUS!$H687 -> 410.20698 | ES7: =IF(ER7>0,EQ7/ER7-1,1) -> -0.84405458 | ET7: =Serviceorderfile_Current!$U688*Serviceorderfile_Current!$H688 -> 391.81564 | EU7: =Serviceorderfile_PREVIOUS!$U688*Serviceorderfile_PREVIOUS!$H688 -> 0 | EV7: =IF(EU7>0,ET7/EU7-1,1) -> 1 | EX7: =Serviceorderfile_Current!$V682 -> #DIV/0! | EY7: =Aged!E95 -> 0 | EZ7: =Serviceorderfile_Current!$U686*Serviceorderfile_Current!$H686 -> 1401.4739 | FA7: =Serviceorderfile_PREVIOUS!$U686*Serviceorderfile_PREVIOUS!$H686 -> 868.39139 | FB7: =IF(FA7>0,EZ7/FA7-1,1) -> 0.61387354 | FD7: =EZ7+ET7+EQ7+EN7+EK7+EH7 -> 10406.037 | FE7: =FA7+EU7+ER7+EO7+EL7+EI7 -> 5732.7692 | FF7: =IF(FE7>0,FD7/FE7-1,1) -> 0.81518505
A8: Iraq | B8: =Serviceorderfile_Current!$W573 -> 5 | C8: =Serviceorderfile_PREVIOUS!$W573 -> 19 | D8: =IF(C8>0,B8/C8-1,1) -> -0.73684211 | E8: ='YOY Orders'!$J40 -> -12 | F8: ='YOY Orders'!$B40 -> 60 | G8: =IF(F8>0,E8/F8-1,1) -> -1.2 | H8: =Serviceorderfile_Current!$W575 -> 65 | I8: =Serviceorderfile_PREVIOUS!$W575 -> 34 | J8: =IF(I8>0,H8/I8-1,1) -> 0.91176471 | K8: ='YOY Orders'!$K40 -> 92 | L8: ='YOY Orders'!$C40 -> 78 | M8: =IF(L8>0,K8/L8-1,1) -> 0.17948718 | N8: =Serviceorderfile_Current!$W574 -> 76 | O8: =Serviceorderfile_PREVIOUS!$W574 -> 151 | P8: =IF(O8>0,N8/O8-1,1) -> -0.49668874 | Q8: ='YOY Orders'!$O40 -> 38 | R8: ='YOY Orders'!$G40 -> 249 | S8: =IF(R8>0,Q8/R8-1,1) -> -0.84738956 | T8: =Serviceorderfile_Current!$W576 -> 12 | U8: =Serviceorderfile_PREVIOUS!$W576 -> 49 | V8: =IF(U8>0,T8/U8-1,1) -> -0.75510204 | W8: ='YOY Orders'!$L40 -> 5 | X8: ='YOY Orders'!$D40 -> 46 | Y8: =IF(X8>0,W8/X8-1,1) -> -0.89130435 | Z8: =Serviceorderfile_Current!$W577 -> 47 | AA8: =Serviceorderfile_PREVIOUS!$W577 -> 36 | AB8: =IF(AA8>0,Z8/AA8-1,1) -> 0.30555556 | AC8: ='YOY Orders'!$N40 -> 17 | AD8: ='YOY Orders'!$F40 -> 0 | AE8: =IF(AD8>0,AC8/AD8-1,1) -> 1 | AF8: =Serviceorderfile_Current!$W571 -> 220 | AG8: =Serviceorderfile_PREVIOUS!$W571 -> 315 | AH8: =IF(AG8>0,AF8/AG8-1,1) -> -0.3015873 | AI8: ='YOY Orders'!$M40 -> 269 | AJ8: ='YOY Orders'!$E40 -> 244 | AK8: =IF(AJ8>0,AI8/AJ8-1,1) -> 0.10245902 | AL8: =B8+T8+Z8+AF8+N8+H8 -> 425 | AM8: =C8+U8+AA8+AG8+O8+I8 -> 604 | AN8: =IF(AM8>0,AL8/AM8-1,1) -> -0.29635762 | AO8: =E8+W8+AC8+AI8+Q8+K8 -> 409 | AP8: =F8+X8+AD8+AJ8+R8+L8 -> 677 | AQ8: =IF(AP8>0,AO8/AP8-1,1) -> -0.39586411 | AS8: Iraq | AT8: =Serviceorderfile_Current!$I573*Serviceorderfile_Current!$U573 -> 0 | AU8: =Serviceorderfile_PREVIOUS!$I573*Serviceorderfile_PREVIOUS!$U573 -> 19 | AV8: =IF(AU8>0,AT8/AU8-1,1) -> -1 | AW8: =AT8/B8 -> 0 | AX8: =AU8/C8 -> 1 | AY8: =(AW8-AX8)*100 -> -100 | AZ8: =Serviceorderfile_Current!$I575*Serviceorderfile_Current!$U575 -> 3 | BA8: =Serviceorderfile_PREVIOUS!$I575*Serviceorderfile_PREVIOUS!$U575 -> 16 | BB8: =IF(BA8>0,AZ8/BA8-1,1) -> -0.8125 | BC8: =AZ8/H8 -> 0.046153846 | BD8: =BA8/I8 -> 0.47058824 | BE8: =(BC8-BD8)*100 -> -42.443439 | BF8: =Serviceorderfile_Current!$I574*Serviceorderfile_Current!$U574 -> 7 | BG8: =Serviceorderfile_PREVIOUS!$I574*Serviceorderfile_PREVIOUS!$U574 -> 41 | BH8: =IF(BG8>0,BF8/BG8-1,1) -> -0.82926829 | BI8: =BF8/N8 -> 0.092105263 | BJ8: =BG8/O8 -> 0.27152318 | BK8: =(BI8-BJ8)*100 -> -17.941792 | BL8: =Serviceorderfile_Current!$I576*Serviceorderfile_Current!$U576 -> 1 | BM8: =Serviceorderfile_PREVIOUS!$I576*Serviceorderfile_PREVIOUS!$U576 -> 5 | BN8: =IF(BM8>0,BL8/BM8-1,1) -> -0.8 | BO8: =BL8/T8 -> 0.083333333 | BP8: =BM8/U8 -> 0.10204082 | BQ8: =(BO8-BP8)*100 -> -1.8707483 | BR8: =Serviceorderfile_Current!$I577*Serviceorderfile_Current!$U577 -> 5 | BS8: =Serviceorderfile_PREVIOUS!$I577*Serviceorderfile_PREVIOUS!$U577 -> 0 | BT8: =IF(BS8>0,BR8/BS8-1,1) -> 1 | BU8: =BR8/Z8 -> 0.10638298 | BV8: =BS8/AA8 -> 0 | BW8: =(BU8-BV8)*100 -> 10.638298 | BX8: =Serviceorderfile_Current!$I571*Serviceorderfile_Current!$U571 -> 44 | BY8: =Serviceorderfile_PREVIOUS!$I571*Serviceorderfile_PREVIOUS!$U571 -> 45 | BZ8: =IF(BY8>0,BX8/BY8-1,1) -> -0.022222222 | CA8: =BX8/AF8 -> 0.2 | CB8: =BY8/AG8 -> 0.14285714 | CC8: =(CA8-CB8)*100 -> 5.7142857 | CD8: =AT8+BL8+BR8+BX8+BF8 -> 57 | CE8: =AU8+BM8+BS8+BY8+BG8 -> 110 | CF8: =IF(CE8>0,CD8/CE8-1,1) -> -0.48181818 | CG8: =CD8/AL8 -> 0.13411765 | CH8: =CE8/AM8 -> 0.18211921 | CI8: =(CG8-CH8)*100 -> -4.8001558 | CK8: Iraq | CL8: =Serviceorderfile_Current!$J573*Serviceorderfile_Current!$U573 -> 4 | CM8: =Serviceorderfile_PREVIOUS!$J573*Serviceorderfile_PREVIOUS!$U573 -> 0 | CN8: =IF(CM8>0,CL8/CM8-1,1) -> 1 | CO8: =Serviceorderfile_Current!$J575*Serviceorderfile_Current!$U575 -> 15 | CP8: =Serviceorderfile_PREVIOUS!$J575*Serviceorderfile_PREVIOUS!$U575 -> 0 | CQ8: =IF(CP8>0,CO8/CP8-1,1) -> 1 | CR8: =Serviceorderfile_Current!$J574*Serviceorderfile_Current!$U574 -> 7 | CS8: =Serviceorderfile_PREVIOUS!$J574*Serviceorderfile_PREVIOUS!$U574 -> 16 | CT8: =IF(CS8>0,CR8/CS8-1,1) -> -0.5625 | CU8: =Serviceorderfile_Current!$J576*Serviceorderfile_Current!$U576 -> 1 | CV8: =Serviceorderfile_PREVIOUS!$J576*Serviceorderfile_PREVIOUS!$U576 -> 5 | CW8: =IF(CV8>0,CU8/CV8-1,1) -> -0.8 | CX8: =Serviceorderfile_Current!$J577*Serviceorderfile_Current!$U577 -> 6 | CY8: =Serviceorderfile_PREVIOUS!$J577*Serviceorderfile_PREVIOUS!$U577 -> 0 | CZ8: =IF(CY8>0,CX8/CY8-1,1) -> 1 | DA8: =Serviceorderfile_Current!$J571*Serviceorderfile_Current!$U571 -> 72 | DB8: =Serviceorderfile_PREVIOUS!$J571*Serviceorderfile_PREVIOUS!$U571 -> 200 | DC8: =IF(DB8>0,DA8/DB8-1,1) -> -0.64 | DD8: =CL8+CO8+CR8+CU8+CX8+DA8 -> 105 | DE8: =CM8+CP8+CS8+CV8+CY8+DB8 -> 221 | DF8: =IF(DE8>0,DD8/DE8-1,1) -> -0.52488688 | DH8: Iraq | DI8: =Serviceorderfile_Current!$K573*Serviceorderfile_Current!$U573 -> 0 | DJ8: =Serviceorderfile_PREVIOUS!$K573*Serviceorderfile_PREVIOUS!$U573 -> 0 | DK8: =IF(DJ8>0,DI8/DJ8-1,1) -> 1 | DL8: =Serviceorderfile_Current!$K575*Serviceorderfile_Current!$U575 -> 5 | DM8: =Serviceorderfile_PREVIOUS!$K575*Serviceorderfile_PREVIOUS!$U575 -> 0 | DN8: =IF(DM8>0,DL8/DM8-1,1) -> 1 | DO8: =Serviceorderfile_Current!$K574*Serviceorderfile_Current!$U574 -> 7 | DP8: =Serviceorderfile_PREVIOUS!$K574*Serviceorderfile_PREVIOUS!$U574 -> 16 | DQ8: =IF(DP8>0,DO8/DP8-1,1) -> -0.5625 | DR8: =Serviceorderfile_Current!$K576*Serviceorderfile_Current!$U576 -> 1 | DS8: =Serviceorderfile_PREVIOUS!$K576*Serviceorderfile_PREVIOUS!$U576 -> 5 | DT8: =IF(DS8>0,DR8/DS8-1,1) -> -0.8 | DU8: =Serviceorderfile_Current!$K577*Serviceorderfile_Current!$U577 -> 0 | DV8: =Serviceorderfile_PREVIOUS!$K577*Serviceorderfile_PREVIOUS!$U577 -> 0 | DW8: =IF(DV8>0,DU8/DV8-1,1) -> 1 | DX8: =Serviceorderfile_Current!$K571*Serviceorderfile_Current!$U571 -> 15 | DY8: =Serviceorderfile_PREVIOUS!$K571*Serviceorderfile_PREVIOUS!$U571 -> 60 | DZ8: =IF(DY8>0,DX8/DY8-1,1) -> -0.75 | EA8: =DI8+DL8+DO8+DR8+DU8+DX8 -> 28 | EB8: =DJ8+DM8+DP8+DS8+DV8+DY8 -> 81 | EC8: =IF(EB8>0,EA8/EB8-1,1) -> -0.65432099 | EE8: Iraq | EF8: =Serviceorderfile_Current!$V570 -> 1 | EG8: =Aged!E35 -> 1 | EH8: =Serviceorderfile_Current!$U565*Serviceorderfile_Current!$H565 -> 735 | EI8: =Serviceorderfile_PREVIOUS!$U565*Serviceorderfile_PREVIOUS!$H565 -> 800 | EJ8: =IF(EI8>0,EH8/EI8-1,1) -> -0.08125 | EK8: =Serviceorderfile_Current!$U567*Serviceorderfile_Current!$H567 -> 297 | EL8: =Serviceorderfile_PREVIOUS!$U567*Serviceorderfile_PREVIOUS!$H567 -> 267 | EM8: =IF(EL8>0,EK8/EL8-1,1) -> 0.11235955 | EN8: =Serviceorderfile_Current!$U566*Serviceorderfile_Current!$H566 -> 301 | EO8: =Serviceorderfile_PREVIOUS!$U566*Serviceorderfile_PREVIOUS!$H566 -> 289 | EP8: =IF(EO8>0,EN8/EO8-1,1) -> 0.041522491 | EQ8: =Serviceorderfile_Current!$U568*Serviceorderfile_Current!$H568 -> 182 | ER8: =Serviceorderfile_PREVIOUS!$U568*Serviceorderfile_PREVIOUS!$H568 -> 67 | ES8: =IF(ER8>0,EQ8/ER8-1,1) -> 1.7164179 | ET8: =Serviceorderfile_Current!$U569*Serviceorderfile_Current!$H569 -> 0 | EU8: =Serviceorderfile_PREVIOUS!$U569*Serviceorderfile_PREVIOUS!$H569 -> 0 | EV8: =IF(EU8>0,ET8/EU8-1,1) -> 1 | EX8: =Serviceorderfile_Current!$V563 -> 1 | EY8: =Aged!E88 -> 0.61 | EZ8: =Serviceorderfile_Current!$U567*Serviceorderfile_Current!$H567 -> 297 | FA8: =Serviceorderfile_PREVIOUS!$U567*Serviceorderfile_PREVIOUS!$H567 -> 267 | FB8: =IF(FA8>0,EZ8/FA8-1,1) -> 0.11235955 | FD8: =EZ8+ET8+EQ8+EN8+EK8+EH8 -> 1812 | FE8: =FA8+EU8+ER8+EO8+EL8+EI8 -> 1690 | FF8: =IF(FE8>0,FD8/FE8-1,1) -> 0.072189349
A9: Nigeria | B9: =Serviceorderfile_Current!$W641 -> 4 | C9: =Serviceorderfile_PREVIOUS!$W641 -> 2 | D9: =IF(C9>0,B9/C9-1,1) -> 1 | E9: ='YOY Orders'!$J41 -> 20 | F9: ='YOY Orders'!$B41 -> 43 | G9: =IF(F9>0,E9/F9-1,1) -> -0.53488372 | H9: =Serviceorderfile_Current!$W643 -> 46 | I9: =Serviceorderfile_PREVIOUS!$W643 -> 45 | J9: =IF(I9>0,H9/I9-1,1) -> 0.022222222 | K9: ='YOY Orders'!$K41 -> 3 | L9: ='YOY Orders'!$C41 -> 1 | M9: =IF(L9>0,K9/L9-1,1) -> 2 | N9: =Serviceorderfile_Current!$W642 -> 0 | O9: =Serviceorderfile_PREVIOUS!$W642 -> 0 | P9: =IF(O9>0,N9/O9-1,1) -> 1 | Q9: ='YOY Orders'!$O41 -> 0 | R9: ='YOY Orders'!$G41 -> 0 | S9: =IF(R9>0,Q9/R9-1,1) -> 1 | T9: =Serviceorderfile_Current!$W644 -> 161 | U9: =Serviceorderfile_PREVIOUS!$W644 -> 115 | V9: =IF(U9>0,T9/U9-1,1) -> 0.4 | W9: ='YOY Orders'!$L41 -> 148 | X9: ='YOY Orders'!$D41 -> 120 | Y9: =IF(X9>0,W9/X9-1,1) -> 0.23333333 | Z9: =Serviceorderfile_Current!$W645 -> 0 | AA9: =Serviceorderfile_PREVIOUS!$W645 -> 2 | AB9: =IF(AA9>0,Z9/AA9-1,1) -> -1 | AC9: ='YOY Orders'!$N41 -> 8 | AD9: ='YOY Orders'!$F41 -> 12 | AE9: =IF(AD9>0,AC9/AD9-1,1) -> -0.33333333 | AF9: =Serviceorderfile_Current!$W639 -> 395 | AG9: =Serviceorderfile_PREVIOUS!$W639 -> 23 | AH9: =IF(AG9>0,AF9/AG9-1,1) -> 16.173913 | AI9: ='YOY Orders'!$M41 -> 598 | AJ9: ='YOY Orders'!$E41 -> 266 | AK9: =IF(AJ9>0,AI9/AJ9-1,1) -> 1.2481203 | AL9: =B9+T9+Z9+AF9+N9+H9 -> 606 | AM9: =C9+U9+AA9+AG9+O9+I9 -> 187 | AN9: =IF(AM9>0,AL9/AM9-1,1) -> 2.2406417 | AO9: =E9+W9+AC9+AI9+Q9+K9 -> 777 | AP9: =F9+X9+AD9+AJ9+R9+L9 -> 442 | AQ9: =IF(AP9>0,AO9/AP9-1,1) -> 0.75791855 | AS9: Nigeria | AT9: =Serviceorderfile_Current!$I641*Serviceorderfile_Current!$U641 -> 4 | AU9: =Serviceorderfile_PREVIOUS!$I641*Serviceorderfile_PREVIOUS!$U641 -> 2 | AV9: =IF(AU9>0,AT9/AU9-1,1) -> 1 | AW9: =AT9/B9 -> 1 | AX9: =AU9/C9 -> 1 | AY9: =(AW9-AX9)*100 -> 0 | AZ9: =Serviceorderfile_Current!$I643*Serviceorderfile_Current!$U643 -> 0 | BA9: =Serviceorderfile_PREVIOUS!$I643*Serviceorderfile_PREVIOUS!$U643 -> 0 | BB9: =IF(BA9>0,AZ9/BA9-1,1) -> 1 | BC9: =AZ9/H9 -> 0 | BD9: =BA9/I9 -> 0 | BE9: =(BC9-BD9)*100 -> 0 | BF9: =Serviceorderfile_Current!$I642*Serviceorderfile_Current!$U642 -> 0 | BG9: =Serviceorderfile_PREVIOUS!$I642*Serviceorderfile_PREVIOUS!$U642 -> 0 | BH9: =IF(BG9>0,BF9/BG9-1,1) -> 1 | BI9: =BF9/N9 -> #DIV/0! | BJ9: =BG9/O9 -> #DIV/0! | BK9: =(BI9-BJ9)*100 -> #DIV/0! | BL9: =Serviceorderfile_Current!$I644*Serviceorderfile_Current!$U644 -> 14 | BM9: =Serviceorderfile_PREVIOUS!$I644*Serviceorderfile_PREVIOUS!$U644 -> 12 | BN9: =IF(BM9>0,BL9/BM9-1,1) -> 0.16666667 | BO9: =BL9/T9 -> 0.086956522 | BP9: =BM9/U9 -> 0.10434783 | BQ9: =(BO9-BP9)*100 -> -1.7391304 | BR9: =Serviceorderfile_Current!$I645*Serviceorderfile_Current!$U645 -> 0 | BS9: =Serviceorderfile_PREVIOUS!$I645*Serviceorderfile_PREVIOUS!$U645 -> 0 | BT9: =IF(BS9>0,BR9/BS9-1,1) -> 1 | BU9: =BR9/Z9 -> #DIV/0! | BV9: =BS9/AA9 -> 0 | BW9: =(BU9-BV9)*100 -> #DIV/0! | BX9: =Serviceorderfile_Current!$I639*Serviceorderfile_Current!$U639 -> 43 | BY9: =Serviceorderfile_PREVIOUS!$I639*Serviceorderfile_PREVIOUS!$U639 -> 18 | BZ9: =IF(BY9>0,BX9/BY9-1,1) -> 1.3888889 | CA9: =BX9/AF9 -> 0.10886076 | CB9: =BY9/AG9 -> 0.7826087 | CC9: =(CA9-CB9)*100 -> -67.374794 | CD9: =AT9+BL9+BR9+BX9+BF9 -> 61 | CE9: =AU9+BM9+BS9+BY9+BG9 -> 32 | CF9: =IF(CE9>0,CD9/CE9-1,1) -> 0.90625 | CG9: =CD9/AL9 -> 0.10066007 | CH9: =CE9/AM9 -> 0.17112299 | CI9: =(CG9-CH9)*100 -> -7.0462929 | CK9: Nigeria | CL9: =Serviceorderfile_Current!$J641*Serviceorderfile_Current!$U641 -> 0 | CM9: =Serviceorderfile_PREVIOUS!$J641*Serviceorderfile_PREVIOUS!$U641 -> 0 | CN9: =IF(CM9>0,CL9/CM9-1,1) -> 1 | CO9: =Serviceorderfile_Current!$J643*Serviceorderfile_Current!$U643 -> 3 | CP9: =Serviceorderfile_PREVIOUS!$J643*Serviceorderfile_PREVIOUS!$U643 -> 45 | CQ9: =IF(CP9>0,CO9/CP9-1,1) -> -0.93333333 | CR9: =Serviceorderfile_Current!$J642*Serviceorderfile_Current!$U642 -> 0 | CS9: =Serviceorderfile_PREVIOUS!$J642*Serviceorderfile_PREVIOUS!$U642 -> 0 | CT9: =IF(CS9>0,CR9/CS9-1,1) -> 1 | CU9: =Serviceorderfile_Current!$J644*Serviceorderfile_Current!$U644 -> 34 | CV9: =Serviceorderfile_PREVIOUS!$J644*Serviceorderfile_PREVIOUS!$U644 -> 16 | CW9: =IF(CV9>0,CU9/CV9-1,1) -> 1.125 | CX9: =Serviceorderfile_Current!$J645*Serviceorderfile_Current!$U645 -> 0 | CY9: =Serviceorderfile_PREVIOUS!$J645*Serviceorderfile_PREVIOUS!$U645 -> 0 | CZ9: =IF(CY9>0,CX9/CY9-1,1) -> 1 | DA9: =Serviceorderfile_Current!$J639*Serviceorderfile_Current!$U639 -> 286 | DB9: =Serviceorderfile_PREVIOUS!$J639*Serviceorderfile_PREVIOUS!$U639 -> 5 | DC9: =IF(DB9>0,DA9/DB9-1,1) -> 56.2 | DD9: =CL9+CO9+CR9+CU9+CX9+DA9 -> 323 | DE9: =CM9+CP9+CS9+CV9+CY9+DB9 -> 66 | DF9: =IF(DE9>0,DD9/DE9-1,1) -> 3.8939394 | DH9: Nigeria | DI9: =Serviceorderfile_Current!$K641*Serviceorderfile_Current!$U641 -> 0 | DJ9: =Serviceorderfile_PREVIOUS!$K641*Serviceorderfile_PREVIOUS!$U641 -> 0 | DK9: =IF(DJ9>0,DI9/DJ9-1,1) -> 1 | DL9: =Serviceorderfile_Current!$K643*Serviceorderfile_Current!$U643 -> 43 | DM9: =Serviceorderfile_PREVIOUS!$K643*Serviceorderfile_PREVIOUS!$U643 -> 0 | DN9: =IF(DM9>0,DL9/DM9-1,1) -> 1 | DO9: =Serviceorderfile_Current!$K642*Serviceorderfile_Current!$U642 -> 0 | DP9: =Serviceorderfile_PREVIOUS!$K642*Serviceorderfile_PREVIOUS!$U642 -> 0 | DQ9: =IF(DP9>0,DO9/DP9-1,1) -> 1 | DR9: =Serviceorderfile_Current!$K644*Serviceorderfile_Current!$U644 -> 13 | DS9: =Serviceorderfile_PREVIOUS!$K644*Serviceorderfile_PREVIOUS!$U644 -> 12 | DT9: =IF(DS9>0,DR9/DS9-1,1) -> 0.083333333 | DU9: =Serviceorderfile_Current!$K645*Serviceorderfile_Current!$U645 -> 0 | DV9: =Serviceorderfile_PREVIOUS!$K645*Serviceorderfile_PREVIOUS!$U645 -> 0 | DW9: =IF(DV9>0,DU9/DV9-1,1) -> 1 | DX9: =Serviceorderfile_Current!$K639*Serviceorderfile_Current!$U639 -> 66 | DY9: =Serviceorderfile_PREVIOUS!$K639*Serviceorderfile_PREVIOUS!$U639 -> 0 | DZ9: =IF(DY9>0,DX9/DY9-1,1) -> 1 | EA9: =DI9+DL9+DO9+DR9+DU9+DX9 -> 122 | EB9: =DJ9+DM9+DP9+DS9+DV9+DY9 -> 12 | EC9: =IF(EB9>0,EA9/EB9-1,1) -> 9.1666667 | EE9: Nigeria | EF9: =Serviceorderfile_Current!$V638 -> 1 | EG9: =Aged!E39 -> 1 | EH9: =Serviceorderfile_Current!$U633*Serviceorderfile_Current!$H633 -> 28 | EI9: =Serviceorderfile_PREVIOUS!$U633*Serviceorderfile_PREVIOUS!$H633 -> 51 | EJ9: =IF(EI9>0,EH9/EI9-1,1) -> -0.45098039 | EK9: =Serviceorderfile_Current!$U635*Serviceorderfile_Current!$H635 -> 560 | EL9: =Serviceorderfile_PREVIOUS!$U635*Serviceorderfile_PREVIOUS!$H635 -> 339 | EM9: =IF(EL9>0,EK9/EL9-1,1) -> 0.6519174 | EN9: =Serviceorderfile_Current!$U634*Serviceorderfile_Current!$H634 -> 0 | EO9: =Serviceorderfile_PREVIOUS!$U634*Serviceorderfile_PREVIOUS!$H634 -> 0 | EP9: =IF(EO9>0,EN9/EO9-1,1) -> 1 | EQ9: =Serviceorderfile_Current!$U636*Serviceorderfile_Current!$H636 -> 232 | ER9: =Serviceorderfile_PREVIOUS!$U636*Serviceorderfile_PREVIOUS!$H636 -> 93 | ES9: =IF(ER9>0,EQ9/ER9-1,1) -> 1.4946237 | ET9: =Serviceorderfile_Current!$U637*Serviceorderfile_Current!$H637 -> 6 | EU9: =Serviceorderfile_PREVIOUS!$U637*Serviceorderfile_PREVIOUS!$H637 -> 0 | EV9: =IF(EU9>0,ET9/EU9-1,1) -> 1 | EX9: =Serviceorderfile_Current!$V631 -> 1 | EY9: =Aged!E92 -> 0.89 | EZ9: =Serviceorderfile_Current!$U635*Serviceorderfile_Current!$H635 -> 560 | FA9: =Serviceorderfile_PREVIOUS!$U635*Serviceorderfile_PREVIOUS!$H635 -> 339 | FB9: =IF(FA9>0,EZ9/FA9-1,1) -> 0.6519174 | FD9: =EZ9+ET9+EQ9+EN9+EK9+EH9 -> 1386 | FE9: =FA9+EU9+ER9+EO9+EL9+EI9 -> 822 | FF9: =IF(FE9>0,FD9/FE9-1,1) -> 0.68613139
A10: Oman | B10: =Serviceorderfile_Current!$W658 -> 0 | C10: =Serviceorderfile_PREVIOUS!$W658 -> 0 | D10: =IF(C10>0,B10/C10-1,1) -> 1 | E10: ='YOY Orders'!$J42 -> 2.6943 | F10: ='YOY Orders'!$B42 -> 1.1547 | G10: =IF(F10>0,E10/F10-1,1) -> 1.3333333 | H10: =Serviceorderfile_Current!$W660 -> 5.0037 | I10: =Serviceorderfile_PREVIOUS!$W660 -> 0 | J10: =IF(I10>0,H10/I10-1,1) -> 1 | K10: ='YOY Orders'!$K42 -> 26.1732 | L10: ='YOY Orders'!$C42 -> 13.0866 | M10: =IF(L10>0,K10/L10-1,1) -> 1 | N10: =Serviceorderfile_Current!$W659 -> 34.641 | O10: =Serviceorderfile_PREVIOUS!$W659 -> 33.8712 | P10: =IF(O10>0,N10/O10-1,1) -> 0.022727273 | Q10: ='YOY Orders'!$O42 -> 13.8564 | R10: ='YOY Orders'!$G42 -> 53.1162 | S10: =IF(R10>0,Q10/R10-1,1) -> -0.73913043 | T10: =Serviceorderfile_Current!$W661 -> 1.1547 | U10: =Serviceorderfile_PREVIOUS!$W661 -> 0 | V10: =IF(U10>0,T10/U10-1,1) -> 1 | W10: ='YOY Orders'!$L42 -> 1.1547 | X10: ='YOY Orders'!$D42 -> -0.3849 | Y10: =IF(X10>0,W10/X10-1,1) -> 1 | Z10: =Serviceorderfile_Current!$W662 -> 0.7698 | AA10: =Serviceorderfile_PREVIOUS!$W662 -> 0 | AB10: =IF(AA10>0,Z10/AA10-1,1) -> 1 | AC10: ='YOY Orders'!$N42 -> 0.7698 | AD10: ='YOY Orders'!$F42 -> 0 | AE10: =IF(AD10>0,AC10/AD10-1,1) -> 1 | AF10: =Serviceorderfile_Current!$W656 -> 35.0259 | AG10: =Serviceorderfile_PREVIOUS!$W656 -> 2.3094 | AH10: =IF(AG10>0,AF10/AG10-1,1) -> 14.166667 | AI10: ='YOY Orders'!$M42 -> 36.9504 | AJ10: ='YOY Orders'!$E42 -> 7.3131 | AK10: =IF(AJ10>0,AI10/AJ10-1,1) -> 4.0526316 | AL10: =B10+T10+Z10+AF10+N10+H10 -> 76.5951 | AM10: =C10+U10+AA10+AG10+O10+I10 -> 36.1806 | AN10: =IF(AM10>0,AL10/AM10-1,1) -> 1.1170213 | AO10: =E10+W10+AC10+AI10+Q10+K10 -> 81.5988 | AP10: =F10+X10+AD10+AJ10+R10+L10 -> 74.2857 | AQ10: =IF(AP10>0,AO10/AP10-1,1) -> 0.098445596 | AS10: Oman | AT10: =Serviceorderfile_Current!$I658*Serviceorderfile_Current!$U658 -> 0 | AU10: =Serviceorderfile_PREVIOUS!$I658*Serviceorderfile_PREVIOUS!$U658 -> 0 | AV10: =IF(AU10>0,AT10/AU10-1,1) -> 1 | AW10: =AT10/B10 -> #DIV/0! | AX10: =AU10/C10 -> #DIV/0! | AY10: =(AW10-AX10)*100 -> #DIV/0! | AZ10: =Serviceorderfile_Current!$I660*Serviceorderfile_Current!$U660 -> 0.7698 | BA10: =Serviceorderfile_PREVIOUS!$I660*Serviceorderfile_PREVIOUS!$U660 -> 0 | BB10: =IF(BA10>0,AZ10/BA10-1,1) -> 1 | BC10: =AZ10/H10 -> 0.15384615 | BD10: =BA10/I10 -> #DIV/0! | BE10: =(BC10-BD10)*100 -> #DIV/0! | BF10: =Serviceorderfile_Current!$I659*Serviceorderfile_Current!$U659 -> 5.0037 | BG10: =Serviceorderfile_PREVIOUS!$I659*Serviceorderfile_PREVIOUS!$U659 -> 13.0866 | BH10: =IF(BG10>0,BF10/BG10-1,1) -> -0.61764706 | BI10: =BF10/N10 -> 0.14444444 | BJ10: =BG10/O10 -> 0.38636364 | BK10: =(BI10-BJ10)*100 -> -24.191919 | BL10: =Serviceorderfile_Current!$I661*Serviceorderfile_Current!$U661 -> 1.1547 | BM10: =Serviceorderfile_PREVIOUS!$I661*Serviceorderfile_PREVIOUS!$U661 -> 0 | BN10: =IF(BM10>0,BL10/BM10-1,1) -> 1 | BO10: =BL10/T10 -> 1 | BP10: =BM10/U10 -> #DIV/0! | BQ10: =(BO10-BP10)*100 -> #DIV/0! | BR10: =Serviceorderfile_Current!$I662*Serviceorderfile_Current!$U662 -> 0 | BS10: =Serviceorderfile_PREVIOUS!$I662*Serviceorderfile_PREVIOUS!$U662 -> 0 | BT10: =IF(BS10>0,BR10/BS10-1,1) -> 1 | BU10: =BR10/Z10 -> 0 | BV10: =BS10/AA10 -> #DIV/0! | BW10: =(BU10-BV10)*100 -> #DIV/0! | BX10: =Serviceorderfile_Current!$I656*Serviceorderfile_Current!$U656 -> 11.547 | BY10: =Serviceorderfile_PREVIOUS!$I656*Serviceorderfile_PREVIOUS!$U656 -> 2.3094 | BZ10: =IF(BY10>0,BX10/BY10-1,1) -> 4 | CA10: =BX10/AF10 -> 0.32967033 | CB10: =BY10/AG10 -> 1 | CC10: =(CA10-CB10)*100 -> -67.032967 | CD10: =AT10+BL10+BR10+BX10+BF10 -> 17.7054 | CE10: =AU10+BM10+BS10+BY10+BG10 -> 15.396 | CF10: =IF(CE10>0,CD10/CE10-1,1) -> 0.15 | CG10: =CD10/AL10 -> 0.23115578 | CH10: =CE10/AM10 -> 0.42553191 | CI10: =(CG10-CH10)*100 -> -19.437614 | CK10: Oman | CL10: =Serviceorderfile_Current!$J658*Serviceorderfile_Current!$U658 -> 0 | CM10: =Serviceorderfile_PREVIOUS!$J658*Serviceorderfile_PREVIOUS!$U658 -> 0 | CN10: =IF(CM10>0,CL10/CM10-1,1) -> 1 | CO10: =Serviceorderfile_Current!$J660*Serviceorderfile_Current!$U660 -> 0 | CP10: =Serviceorderfile_PREVIOUS!$J660*Serviceorderfile_PREVIOUS!$U660 -> 0 | CQ10: =IF(CP10>0,CO10/CP10-1,1) -> 1 | CR10: =Serviceorderfile_Current!$J659*Serviceorderfile_Current!$U659 -> 3.849 | CS10: =Serviceorderfile_PREVIOUS!$J659*Serviceorderfile_PREVIOUS!$U659 -> 6.5433 | CT10: =IF(CS10>0,CR10/CS10-1,1) -> -0.41176471 | CU10: =Serviceorderfile_Current!$J661*Serviceorderfile_Current!$U661 -> 0 | CV10: =Serviceorderfile_PREVIOUS!$J661*Serviceorderfile_PREVIOUS!$U661 -> 0 | CW10: =IF(CV10>0,CU10/CV10-1,1) -> 1 | CX10: =Serviceorderfile_Current!$J662*Serviceorderfile_Current!$U662 -> 0 | CY10: =Serviceorderfile_PREVIOUS!$J662*Serviceorderfile_PREVIOUS!$U662 -> 0 | CZ10: =IF(CY10>0,CX10/CY10-1,1) -> 1 | DA10: =Serviceorderfile_Current!$J656*Serviceorderfile_Current!$U656 -> 11.547 | DB10: =Serviceorderfile_PREVIOUS!$J656*Serviceorderfile_PREVIOUS!$U656 -> 0 | DC10: =IF(DB10>0,DA10/DB10-1,1) -> 1 | DD10: =CL10+CO10+CR10+CU10+CX10+DA10 -> 15.396 | DE10: =CM10+CP10+CS10+CV10+CY10+DB10 -> 6.5433 | DF10: =IF(DE10>0,DD10/DE10-1,1) -> 1.3529412 | DH10: Oman | DI10: =Serviceorderfile_Current!$K658*Serviceorderfile_Current!$U658 -> 0 | DJ10: =Serviceorderfile_PREVIOUS!$K658*Serviceorderfile_PREVIOUS!$U658 -> 0 | DK10: =IF(DJ10>0,DI10/DJ10-1,1) -> 1 | DL10: =Serviceorderfile_Current!$K660*Serviceorderfile_Current!$U660 -> 3.849 | DM10: =Serviceorderfile_PREVIOUS!$K660*Serviceorderfile_PREVIOUS!$U660 -> 0 | DN10: =IF(DM10>0,DL10/DM10-1,1) -> 1 | DO10: =Serviceorderfile_Current!$K659*Serviceorderfile_Current!$U659 -> 2.6943 | DP10: =Serviceorderfile_PREVIOUS!$K659*Serviceorderfile_PREVIOUS!$U659 -> 3.0792 | DQ10: =IF(DP10>0,DO10/DP10-1,1) -> -0.125 | DR10: =Serviceorderfile_Current!$K661*Serviceorderfile_Current!$U661 -> 0 | DS10: =Serviceorderfile_PREVIOUS!$K661*Serviceorderfile_PREVIOUS!$U661 -> 0 | DT10: =IF(DS10>0,DR10/DS10-1,1) -> 1 | DU10: =Serviceorderfile_Current!$K662*Serviceorderfile_Current!$U662 -> 0 | DV10: =Serviceorderfile_PREVIOUS!$K662*Serviceorderfile_PREVIOUS!$U662 -> 0 | DW10: =IF(DV10>0,DU10/DV10-1,1) -> 1 | DX10: =Serviceorderfile_Current!$K656*Serviceorderfile_Current!$U656 -> 0 | DY10: =Serviceorderfile_PREVIOUS!$K656*Serviceorderfile_PREVIOUS!$U656 -> 0 | DZ10: =IF(DY10>0,DX10/DY10-1,1) -> 1 | EA10: =DI10+DL10+DO10+DR10+DU10+DX10 -> 6.5433 | EB10: =DJ10+DM10+DP10+DS10+DV10+DY10 -> 3.0792 | EC10: =IF(EB10>0,EA10/EB10-1,1) -> 1.125 | EE10: Oman | EF10: =Serviceorderfile_Current!$V655 -> 0.97965116 | EG10: =Aged!E40 -> 0.99 | EH10: =Serviceorderfile_Current!$U650*Serviceorderfile_Current!$H650 -> 20.3997 | EI10: =Serviceorderfile_PREVIOUS!$U616*Serviceorderfile_PREVIOUS!$H616 -> 203 | EJ10: =IF(EI10>0,EH10/EI10-1,1) -> -0.89950887 | EK10: =Serviceorderfile_Current!$U652*Serviceorderfile_Current!$H652 -> 27.7128 | EL10: =Serviceorderfile_PREVIOUS!$U618*Serviceorderfile_PREVIOUS!$H618 -> 2348 | EM10: =IF(EL10>0,EK10/EL10-1,1) -> -0.98819727 | EN10: =Serviceorderfile_Current!$U651*Serviceorderfile_Current!$H651 -> 84.2931 | EO10: =Serviceorderfile_PREVIOUS!$U651*Serviceorderfile_PREVIOUS!$H651 -> 0 | EP10: =IF(EO10>0,EN10/EO10-1,1) -> 1 | EQ10: =Serviceorderfile_Current!$U653*Serviceorderfile_Current!$H653 -> 0 | ER10: =Serviceorderfile_PREVIOUS!$U653*Serviceorderfile_PREVIOUS!$H653 -> 4.6188 | ES10: =IF(ER10>0,EQ10/ER10-1,1) -> -1 | ET10: =Serviceorderfile_Current!$U654*Serviceorderfile_Current!$H654 -> 0 | EU10: =Serviceorderfile_PREVIOUS!$U654*Serviceorderfile_PREVIOUS!$H654 -> 0 | EV10: =IF(EU10>0,ET10/EU10-1,1) -> 1 | EX10: =Serviceorderfile_Current!$V648 -> 0 | EY10: =Aged!E93 -> 0 | EZ10: =Serviceorderfile_Current!$U652*Serviceorderfile_Current!$H652 -> 27.7128 | FA10: =Serviceorderfile_PREVIOUS!$U652*Serviceorderfile_PREVIOUS!$H652 -> 40.0296 | FB10: =IF(FA10>0,EZ10/FA10-1,1) -> -0.30769231 | FD10: =EZ10+ET10+EQ10+EN10+EK10+EH10 -> 160.1184 | FE10: =FA10+EU10+ER10+EO10+EL10+EI10 -> 2595.6484 | FF10: =IF(FE10>0,FD10/FE10-1,1) -> -0.93831275
